Workbook
Name Slicer_deal_category: #N/A
Name Slicer_lead_type: #N/A
Name Slicer_origin: #N/A

Sheet leads
A1: mql_id | B1: first_contact_date | C1: landing_page_id | D1: origin
A2: dac32acd4db4c29c230538b72f8dd87d | B2: 43132 | C2: 88740e65d5d6b056e0cda098e1ea6313 | D2: social
A3: 8c18d1de7f67e60dbd64e3c07d7e9d5d | B3: 43028 | C3: 007f9098284a86ee80ddeb25d53e0af8 | D3: paid_search
A4: b4bc852d233dfefc5131f593b538befa | B4: 43181 | C4: a7982125ff7aa3b2054c6e44f9d28522 | D4: organic_search
A5: 6be030b81c75970747525b843c1ef4f8 | B5: 43122 | C5: d45d558f0daeecf3cccdffe3c59684aa | D5: email
A6: 5420aad7fec3549a85876ba1c529bd84 | B6: 43152 | C6: b48ec5f3b04e9068441002a19df93c6c | D6: organic_search
A7: 28bdfd5f057764b54c38770f95c69f2f | B7: 43114 | C7: 22c29808c4f815213303f8933030604c | D7: organic_search
A8: 126a0d10becbaafcb2e72ce6848cf32c | B8: 43235 | C8: 6a110e795dd487f1cf8d7583671987af | D8: email
A9: f76136f54d14a3345951f25b7932366b | B9: 43244 | C9: d51b0d02f063ba1d053db6d97226eec3 | D9: email
A10: 2f838cade4a6012a6cb1016d1d8d95ed | B10: 43049 | C10: aeac92c0f5ae22a04ed3b746cce3a1b6 | D10: organic_search
A11: 7281942387a1a0c3f72a50a8b0bb0920 | B11: 43094 | C11: 88740e65d5d6b056e0cda098e1ea6313 | D11: social
A12: c534e2f89539e866011e1e75adfefbfb | B12: 43124 | C12: f017be4dbf86243af5c1ebed0cff36a2 | D12: unknown
A13: c3764ab3fed8fbf556c87fdeaea744a9 | B13: 43220 | C13: 35c9b150ab36fe584c1f24fd458c453a | D13: paid_search
... A8001: 8a6492305a5fbcdcdd1a7f5a90764c07 | B8001: 43111 | C8001: b76ef37428e6799c421989521c0e5077 | D8001: direct_traffic

Sheet Pivot Table
A1: Sum of declared_monthly_revenue | B1: deal_category
A2: origin | B2: High Values | C2: No Revenue | D2: Stander | E2: Grand Total
A3: direct_traffic | B3: 60000 | C3: 0 | D3: 0 | E3: 60000
A4: display | B4: 0 | C4: 0 | D4: 0 | E4: 0
A5: email | B5: 15000 | C5: 0 | D5: 0 | E5: 15000
A6: organic_search | B6: 51415000 | C6: 0 | D6: 11000 | E6: 51426000
A7: other | B7: 0 | C7: 0 | D7: 0 | E7: 0
A8: other_publicities | B8: 0 | C8: 0 | D8: 0 | E8: 0
A9: paid_search | B9: 9165000 | C9: 0 | D9: 4000 | E9: 9169000
A10: referral | B10: 0 | C10: 0 | D10: 0 | E10: 0
A11: social | B11: 500000 | C11: 0 | D11: 1000 | E11: 501000
A12: Unknow | B12: 150000 | C12: 0 | D12: 0 | E12: 150000
A13: unknown | B13: 450000 | C13: 0 | D13: 13006 | E13: 463006
A14: Grand Total | B14: 61755000 | C14: 0 | D14: 29006 | E14: 61784006

Sheet deals
A1: mql_id | B1: seller_id | C1: sdr_id | D1: sr_id | E1: won_date | F1: business_segment | G1: lead_type | H1: lead_behaviour_profile | I1: has_company | J1: has_gtin | K1: average_stock | L1: business_type | M1: declared_product_catalog_size | N1: declared_monthly_revenue | O1: origin | P1: deal_category
A2: 5420aad7fec3549a85876ba1c529bd84 | B2: 2c43fb513632d29b3b58df74816f1b06 | C2: a8387c01a09e99ce014107505b92388c | D2: 4ef15afb4b2723d8f3d81e51ec7afefe | E2: 43157.833 | F2: pet | G2: online_medium | H2: cat | I2: Unknow | J2: Unknow | K2: Unknow | L2: reseller | M2: 0 | N2: 0 | O2: =_xlfn.XLOOKUP(olist_closed_deals_dataset[[#This Row],[mql_id]], leads!A:A, leads!D:D, "Unknow" ) -> organic_search | P2: =IF(olist_closed_deals_dataset[[#This Row],[declared_monthly_revenue]] >= 10000, "High Values ", IF(olist_closed_deals_dataset[[#This Row],[declared_monthly_revenue]] > 0, "Stander ", "No Revenue " )) -> No Revenue
A3: a555fb36b9368110ede0f043dfc3b9a0 | B3: bbb7d7893a450660432ea6652310ebb7 | C3: 09285259593c61296eef10c734121d5b | D3: d3d1e91a157ea7f90548eef82f1955e3 | E3: 43228.846 | F3: car_accessories | G3: industry | H3: eagle | I3: Unknow | J3: Unknow | K3: Unknow | L3: reseller | M3: 0 | N3: 0 | O3: =_xlfn.XLOOKUP(olist_closed_deals_dataset[[#This Row],[mql_id]], leads!A:A, leads!D:D, "Unknow" ) -> referral | P3: =IF(olist_closed_deals_dataset[[#This Row],[declared_monthly_revenue]] >= 10000, "High Values ", IF(olist_closed_deals_dataset[[#This Row],[declared_monthly_revenue]] > 0, "Stander ", "No Revenue " )) -> No Revenue
A4: 327174d3648a2d047e8940d7d15204ca | B4: 612170e34b97004b3ba37eae81836b4c | C4: b90f87164b5f8c2cfa5c8572834dbe3f | D4: 6565aa9ce3178a5caf6171827af3a9ba | E4: 43256.727 | F4: home_appliances | G4: online_big | H4: cat | I4: Unknow | J4: Unknow | K4: Unknow | L4: reseller | M4: 0 | N4: 0 | O4: =_xlfn.XLOOKUP(olist_closed_deals_dataset[[#This Row],[mql_id]], leads!A:A, leads!D:D, "Unknow" ) -> organic_search | P4: =IF(olist_closed_deals_dataset[[#This Row],[declared_monthly_revenue]] >= 10000, "High Values ", IF(olist_closed_deals_dataset[[#This Row],[declared_monthly_revenue]] > 0, "Stander ", "No Revenue " )) -> No Revenue
A5: f5fee8f7da74f4887f5bcae2bafb6dd6 | B5: 21e1781e36faf92725dde4730a88ca0f | C5: 56bf83c4bb35763a51c2baab501b4c67 | D5: d3d1e91a157ea7f90548eef82f1955e3 | E5: 43117.577 | F5: food_drink | G5: online_small | H5: Unknow | I5: Unknow | J5: Unknow | K5: Unknow | L5: reseller | M5: 0 | N5: 0 | O5: =_xlfn.XLOOKUP(olist_closed_deals_dataset[[#This Row],[mql_id]], leads!A:A, leads!D:D, "Unknow" ) -> paid_search | P5: =IF(olist_closed_deals_dataset[[#This Row],[declared_monthly_revenue]] >= 10000, "High Values ", IF(olist_closed_deals_dataset[[#This Row],[declared_monthly_revenue]] > 0, "Stander ", "No Revenue " )) -> No Revenue
A6: ffe640179b554e295c167a2f6be528e0 | B6: ed8cb7b190ceb6067227478e48cf8dde | C6: 4b339f9567d060bcea4f5136b9f5949e | D6: d3d1e91a157ea7f90548eef82f1955e3 | E6: 43284.846 | F6: home_appliances | G6: industry | H6: wolf | I6: Unknow | J6: Unknow | K6: Unknow | L6: manufacturer | M6: 0 | N6: 0 | O6: =_xlfn.XLOOKUP(olist_closed_deals_dataset[[#This Row],[mql_id]], leads!A:A, leads!D:D, "Unknow" ) -> unknown | P6: =IF(olist_closed_deals_dataset[[#This Row],[declared_monthly_revenue]] >= 10000, "High Values ", IF(olist_closed_deals_dataset[[#This Row],[declared_monthly_revenue]] > 0, "Stander ", "No Revenue " )) -> No Revenue
A7: b94fba7670eeb44dce2a0d8eb790e9f5 | B7: 1c742ac33582852aaf3bcfbf5893abcf | C7: fdb16d3cbbeb5798f2f66c4096be026d | D7: 495d4e95a8cf8bbf8b432b612a2aa328 | E7: 43138.753 | F7: health_beauty | G7: online_medium | H7: Unknow | I7: Unknow | J7: Unknow | K7: Unknow | L7: manufacturer | M7: 0 | N7: 0 | O7: =_xlfn.XLOOKUP(olist_closed_deals_dataset[[#This Row],[mql_id]], leads!A:A, leads!D:D, "Unknow" ) -> organic_search | P7: =IF(olist_closed_deals_dataset[[#This Row],[declared_monthly_revenue]] >= 10000, "High Values ", IF(olist_closed_deals_dataset[[#This Row],[declared_monthly_revenue]] > 0, "Stander ", "No Revenue " )) -> No Revenue
A8: c3e30ed7ac989117c7e1e719b4ac128f | B8: 92d7568ad0c5c76fd7d341b2d46f24d6 | C8: 4b339f9567d060bcea4f5136b9f5949e | D8: 85fc447d336637ba1df43e793199fbc8 | E8: 43206.763 | F8: computers | G8: online_medium | H8: wolf | I8: Unknow | J8: Unknow | K8: Unknow | L8: reseller | M8: 0 | N8: 0 | O8: =_xlfn.XLOOKUP(olist_closed_deals_dataset[[#This Row],[mql_id]], leads!A:A, leads!D:D, "Unknow" ) -> direct_traffic | P8: =IF(olist_closed_deals_dataset[[#This Row],[declared_monthly_revenue]] >= 10000, "High Values ", IF(olist_closed_deals_dataset[[#This Row],[declared_monthly_revenue]] > 0, "Stander ", "No Revenue " )) -> No Revenue
A9: b02c89251106e1fdd9d92744be9f94f2 | B9: 44ed138eca6214d572ce1d813fb0049b | C9: 34d40cdaf94010a1d05b0d6212f9e909 | D9: 4ef15afb4b2723d8f3d81e51ec7afefe | E9: 43207.71 | F9: health_beauty | G9: offline | H9: cat | I9: Unknow | J9: Unknow | K9: Unknow | L9: manufacturer | M9: 0 | N9: 0 | O9: =_xlfn.XLOOKUP(olist_closed_deals_dataset[[#This Row],[mql_id]], leads!A:A, leads!D:D, "Unknow" ) -> unknown | P9: =IF(olist_closed_deals_dataset[[#This Row],[declared_monthly_revenue]] >= 10000, "High Values ", IF(olist_closed_deals_dataset[[#This Row],[declared_monthly_revenue]] > 0, "Stander ", "No Revenue " )) -> No Revenue
A10: a90a37898cc5f2718385a2fb981caaff | B10: 0b28859cd04d23edefee9c591fb03cd8 | C10: f42a2bd194f7802ab052a815c8de65b7 | D10: 6565aa9ce3178a5caf6171827af3a9ba | E10: 43234.776 | F10: household_utilities | G10: offline | H10: eagle | I10: Unknow | J10: Unknow | K10: Unknow | L10: reseller | M10: 0 | N10: 0 | O10: =_xlfn.XLOOKUP(olist_closed_deals_dataset[[#This Row],[mql_id]], leads!A:A, leads!D:D, "Unknow" ) -> social | P10: =IF(olist_closed_deals_dataset[[#This Row],[declared_monthly_revenue]] >= 10000, "High Values ", IF(olist_closed_deals_dataset[[#This Row],[declared_monthly_revenue]] > 0, "Stander ", "No Revenue " )) -> No Revenue
A11: 0173e8d8b1d94a355b440fb67388f532 | B11: 87d73636a3acf123e842bb890a4db036 | C11: 9d12ef1a7eca3ec58c545c678af7869c | D11: 9e4d1098a3b0f5da39b0bc48f9876645 | E11: 43214.125 | F11: household_utilities | G11: online_medium | H11: eagle | I11: Unknow | J11: Unknow | K11: Unknow | L11: manufacturer | M11: 0 | N11: 0 | O11: =_xlfn.XLOOKUP(olist_closed_deals_dataset[[#This Row],[mql_id]], leads!A:A, leads!D:D, "Unknow" ) -> paid_search | P11: =IF(olist_closed_deals_dataset[[#This Row],[declared_monthly_revenue]] >= 10000, "High Values ", IF(olist_closed_deals_dataset[[#This Row],[declared_monthly_revenue]] > 0, "Stander ", "No Revenue " )) -> No Revenue
A12: 4e4e70d504b4c0006c8287dedc99d0fc | B12: f7a0d94e966c5665355a182d5b199fcf | C12: fdb16d3cbbeb5798f2f66c4096be026d | D12: 4ef15afb4b2723d8f3d81e51ec7afefe | E12: 43159.821 | F12: construction_tools_house_garden | G12: online_medium | H12: cat | I12: Unknow | J12: Unknow | K12: Unknow | L12: reseller | M12: 0 | N12: 0 | O12: =_xlfn.XLOOKUP(olist_closed_deals_dataset[[#This Row],[mql_id]], leads!A:A, leads!D:D, "Unknow" ) -> social | P12: =IF(olist_closed_deals_dataset[[#This Row],[declared_monthly_revenue]] >= 10000, "High Values ", IF(olist_closed_deals_dataset[[#This Row],[declared_monthly_revenue]] > 0, "Stander ", "No Revenue " )) -> No Revenue
A13: 408a9c4a79800232ac656249af3162eb | B13: b566ab0ef88016e00422755e305103c6 | C13: de63de0d10a6012430098db33c679b0b | D13: d3d1e91a157ea7f90548eef82f1955e3 | E13: 43154.58 | F13: construction_tools_house_garden | G13: online_big | H13: cat | I13: Unknow | J13: Unknow | K13: Unknow | L13: reseller | M13: 0 | N13: 0 | O13: =_xlfn.XLOOKUP(olist_closed_deals_dataset[[#This Row],[mql_id]], leads!A:A, leads!D:D, "Unknow" ) -> paid_search | P13: =IF(olist_closed_deals_dataset[[#This Row],[declared_monthly_revenue]] >= 10000, "High Values ", IF(olist_closed_deals_dataset[[#This Row],[declared_monthly_revenue]] > 0, "Stander ", "No Revenue " )) -> No Revenue
... A31: 9a6b65aedf8177783035f3a53ca21ed1 | B31: 0975b0dd18febd1008391fa53dff0891 | C31: 370c9f455f93a9a96cbe9bea48e70033 | D31: 85fc447d336637ba1df43e793199fbc8 | E31: 43208.751 | F31: party | G31: online_medium | H31: eagle | I31: Unknow | J31: Unknow | K31: Unknow | L31: manufacturer | M31: 0 | N31: 0 | O31: =_xlfn.XLOOKUP(olist_closed_deals_dataset[[#This Row],[mql_id]], leads!A:A, leads!D:D, "Unknow" ) -> organic_search | P31: =IF(olist_closed_deals_dataset[[#This Row],[declared_monthly_revenue]] >= 10000, "High Values ", IF(olist_closed_deals_dataset[[#This Row],[declared_monthly_revenue]] > 0, "Stander ", "No Revenue " )) -> No Revenue
A32: 4bb1ec1ff58ad39558e8468054bfc469 | B32: 4fae87d32467e18eb46e4a76a0a0b9ce | C32: 9d12ef1a7eca3ec58c545c678af7869c | D32: a8387c01a09e99ce014107505b92388c | E32: 43300.754 | F32: small_appliances | G32: online_medium | H32: cat | I32: TRUE | J32: TRUE | K32: 20-50 | L32: reseller | M32: 0 | N32: 0 | O32: =_xlfn.XLOOKUP(olist_closed_deals_dataset[[#This Row],[mql_id]], leads!A:A, leads!D:D, "Unknow" ) -> organic_search | P32: =IF(olist_closed_deals_dataset[[#This Row],[declared_monthly_revenue]] >= 10000, "High Values ", IF(olist_closed_deals_dataset[[#This Row],[declared_monthly_revenue]] > 0, "Stander ", "No Revenue " )) -> No Revenue
A33: c34eb63cd098bf4be03d53462d7ecba2 | B33: 3525be8392a4fa3274c459bcfee41eef | C33: 4b339f9567d060bcea4f5136b9f5949e | D33: de63de0d10a6012430098db33c679b0b | E33: 43285.63 | F33: food_supplement | G33: online_small | H33: cat | I33: Unknow | J33: Unknow | K33: Unknow | L33: reseller | M33: 0 | N33: 0 | O33: =_xlfn.XLOOKUP(olist_closed_deals_dataset[[#This Row],[mql_id]], leads!A:A, leads!D:D, "Unknow" ) -> unknown | P33: =IF(olist_closed_deals_dataset[[#This Row],[declared_monthly_revenue]] >= 10000, "High Values ", IF(olist_closed_deals_dataset[[#This Row],[declared_monthly_revenue]] > 0, "Stander ", "No Revenue " )) -> No Revenue
A34: e428d5580f729d23e6070e43c492e424 | B34: 8b181ee5518df84f18f4e1a43fe07923 | C34: 09285259593c61296eef10c734121d5b | D34: de63de0d10a6012430098db33c679b0b | E34: 43215.125 | F34: health_beauty | G34: online_medium | H34: shark | I34: Unknow | J34: Unknow | K34: Unknow | L34: reseller | M34: 0 | N34: 0 | O34: =_xlfn.XLOOKUP(olist_closed_deals_dataset[[#This Row],[mql_id]], leads!A:A, leads!D:D, "Unknow" ) -> unknown | P34: =IF(olist_closed_deals_dataset[[#This Row],[declared_monthly_revenue]] >= 10000, "High Values ", IF(olist_closed_deals_dataset[[#This Row],[declared_monthly_revenue]] > 0, "Stander ", "No Revenue " )) -> No Revenue
A35: e3c91316d8f28b18d96869aebbb7c3ec | B35: d594982fd877af63ace38ea1fca27c76 | C35: 09285259593c61296eef10c734121d5b | D35: fbf4aef3f6915dc0c3c97d6812522f6a | E35: 43256.723 | F35: audio_video_electronics | G35: industry | H35: wolf | I35: Unknow | J35: Unknow | K35: Unknow | L35: reseller | M35: 0 | N35: 0 | O35: =_xlfn.XLOOKUP(olist_closed_deals_dataset[[#This Row],[mql_id]], leads!A:A, leads!D:D, "Unknow" ) -> organic_search | P35: =IF(olist_closed_deals_dataset[[#This Row],[declared_monthly_revenue]] >= 10000, "High Values ", IF(olist_closed_deals_dataset[[#This Row],[declared_monthly_revenue]] > 0, "Stander ", "No Revenue " )) -> No Revenue
A36: 72e81de94dfc0373b006ca75e9c851a1 | B36: 2f1e89e231b096f4ff1f55dfe8607a7b | C36: e7dff61b78bebffa71678e126ce669ad | D36: 068066e24f0c643eb1d089c7dd20cd73 | E36: 43404.705 | F36: computers | G36: online_medium | H36: cat | I36: TRUE | J36: Unknow | K36: 1-5 | L36: reseller | M36: 80 | N36: 0 | O36: =_xlfn.XLOOKUP(olist_closed_deals_dataset[[#This Row],[mql_id]], leads!A:A, leads!D:D, "Unknow" ) -> paid_search | P36: =IF(olist_closed_deals_dataset[[#This Row],[declared_monthly_revenue]] >= 10000, "High Values ", IF(olist_closed_deals_dataset[[#This Row],[declared_monthly_revenue]] > 0, "Stander ", "No Revenue " )) -> No Revenue
A37: 1cbfa9c878ef8692c1ae21e4cfa11000 | B37: 90269579385b838ce9bd577dcec278a4 | C37: 34d40cdaf94010a1d05b0d6212f9e909 | D37: 85fc447d336637ba1df43e793199fbc8 | E37: 43250.614 | F37: pet | G37: industry | H37: cat | I37: Unknow | J37: Unknow | K37: Unknow | L37: manufacturer | M37: 0 | N37: 0 | O37: =_xlfn.XLOOKUP(olist_closed_deals_dataset[[#This Row],[mql_id]], leads!A:A, leads!D:D, "Unknow" ) -> paid_search | P37: =IF(olist_closed_deals_dataset[[#This Row],[declared_monthly_revenue]] >= 10000, "High Values ", IF(olist_closed_deals_dataset[[#This Row],[declared_monthly_revenue]] > 0, "Stander ", "No Revenue " )) -> No Revenue
A38: b055fc7de322786cd9ddc996cb6e72ff | B38: 398cb257329ef7af7f1943a8974a3cbc | C38: a8387c01a09e99ce014107505b92388c | D38: 9ae085775a198122c5586fa830ff7f2b | E38: 43165.518 | F38: food_drink | G38: online_medium | H38: cat | I38: Unknow | J38: Unknow | K38: Unknow | L38: manufacturer | M38: 0 | N38: 0 | O38: =_xlfn.XLOOKUP(olist_closed_deals_dataset[[#This Row],[mql_id]], leads!A:A, leads!D:D, "Unknow" ) -> organic_search | P38: =IF(olist_closed_deals_dataset[[#This Row],[declared_monthly_revenue]] >= 10000, "High Values ", IF(olist_closed_deals_dataset[[#This Row],[declared_monthly_revenue]] > 0, "Stander ", "No Revenue " )) -> No Revenue
A39: a8d2884db49e0769ad4a0b8dce2e143c | B39: d65f74c704563bcb8baa915fbf8cfa1e | C39: 6aa3b86a83d784b05f0e37e26b20860d | D39: de63de0d10a6012430098db33c679b0b | E39: 43370.522 | F39: health_beauty | G39: online_medium | H39: cat | I39: Unknow | J39: FALSE | K39: Unknow | L39: reseller | M39: 15 | N39: 20000 | O39: =_xlfn.XLOOKUP(olist_closed_deals_dataset[[#This Row],[mql_id]], leads!A:A, leads!D:D, "Unknow" ) -> unknown | P39: =IF(olist_closed_deals_dataset[[#This Row],[declared_monthly_revenue]] >= 10000, "High Values ", IF(olist_closed_deals_dataset[[#This Row],[declared_monthly_revenue]] > 0, "Stander ", "No Revenue " )) -> High Values
A40: d955b97b28c2966211c9de2fe22fefbd | B40: 26e2c91ef821e1ff8985f408788fe35b | C40: 4b339f9567d060bcea4f5136b9f5949e | D40: 6565aa9ce3178a5caf6171827af3a9ba | E40: 43137.657 | F40: bed_bath_table | G40: online_beginner | H40: Unknow | I40: Unknow | J40: Unknow | K40: Unknow | L40: manufacturer | M40: 0 | N40: 0 | O40: =_xlfn.XLOOKUP(olist_closed_deals_dataset[[#This Row],[mql_id]], leads!A:A, leads!D:D, "Unknow" ) -> direct_traffic | P40: =IF(olist_closed_deals_dataset[[#This Row],[declared_monthly_revenue]] >= 10000, "High Values ", IF(olist_closed_deals_dataset[[#This Row],[declared_monthly_revenue]] > 0, "Stander ", "No Revenue " )) -> No Revenue
A41: 1d7cc0f1d0b54eac3609c5222246595b | B41: dedcab67899479e4ea5dcc4eba47f587 | C41: 56bf83c4bb35763a51c2baab501b4c67 | D41: d3d1e91a157ea7f90548eef82f1955e3 | E41: 43235.754 | F41: car_accessories | G41: online_medium | H41: Unknow | I41: Unknow | J41: Unknow | K41: Unknow | L41: reseller | M41: 0 | N41: 0 | O41: =_xlfn.XLOOKUP(olist_closed_deals_dataset[[#This Row],[mql_id]], leads!A:A, leads!D:D, "Unknow" ) -> unknown | P41: =IF(olist_closed_deals_dataset[[#This Row],[declared_monthly_revenue]] >= 10000, "High Values ", IF(olist_closed_deals_dataset[[#This Row],[declared_monthly_revenue]] > 0, "Stander ", "No Revenue " )) -> No Revenue
A42: 78f9eb91b8c7b3b3967fab18283ec614 | B42: ca4b77513ac2040591b0d8fae6958380 | C42: 370c9f455f93a9a96cbe9bea48e70033 | D42: a8387c01a09e99ce014107505b92388c | E42: 43262.528 | F42: health_beauty | G42: online_medium | H42: cat | I42: Unknow | J42: Unknow | K42: Unknow | L42: reseller | M42: 0 | N42: 0 | O42: =_xlfn.XLOOKUP(olist_closed_deals_dataset[[#This Row],[mql_id]], leads!A:A, leads!D:D, "Unknow" ) -> social | P42: =IF(olist_closed_deals_dataset[[#This Row],[declared_monthly_revenue]] >= 10000, "High Values ", IF(olist_closed_deals_dataset[[#This Row],[declared_monthly_revenue]] > 0, "Stander ", "No Revenue " )) -> No Revenue
A43: 20fcec0873b39b4df3df34140d77d6e7 | B43: cee3c487c56d29554a22d112af618301 | C43: 084b6fbb10729ed4da8c3d3f5a3ae7c9 | D43: 0a0fb2b07d841f84fb6714e35c723075 | E43: 43418.753 | F43: other | G43: other | H43: cat | I43: FALSE | J43: FALSE | K43: 1-5 | L43: other | M43: 120 | N43: 6000 | O43: =_xlfn.XLOOKUP(olist_closed_deals_dataset[[#This Row],[mql_id]], leads!A:A, leads!D:D, "Unknow" ) -> organic_search | P43: =IF(olist_closed_deals_dataset[[#This Row],[declared_monthly_revenue]] >= 10000, "High Values ", IF(olist_closed_deals_dataset[[#This Row],[declared_monthly_revenue]] > 0, "Stander ", "No Revenue " )) -> Stander
A44: 0a1643cb73c25878cc845d5594059afe | B44: ae9d6bb89361dff26edbccc7e1c2911d | C44: 068066e24f0c643eb1d089c7dd20cd73 | D44: 2695de1affa7750089c0455f8ce27021 | E44: 43217.584 | F44: fashion_accessories | G44: online_beginner | H44: cat | I44: Unknow | J44: Unknow | K44: Unknow | L44: manufacturer | M44: 0 | N44: 0 | O44: =_xlfn.XLOOKUP(olist_closed_deals_dataset[[#This Row],[mql_id]], leads!A:A, leads!D:D, "Unknow" ) -> organic_search | P44: =IF(olist_closed_deals_dataset[[#This Row],[declared_monthly_revenue]] >= 10000, "High Values ", IF(olist_closed_deals_dataset[[#This Row],[declared_monthly_revenue]] > 0, "Stander ", "No Revenue " )) -> No Revenue
A45: 92c7eacf759c266a7663d63876d84223 | B45: da3eab58892c04039f4cd5ecb09ae260 | C45: 9d12ef1a7eca3ec58c545c678af7869c | D45: c638112b43f1d1b86dcabb0da720c901 | E45: 43186.801 | F45: home_decor | G45: offline | H45: eagle | I45: Unknow | J45: Unknow | K45: Unknow | L45: manufacturer | M45: 0 | N45: 0 | O45: =_xlfn.XLOOKUP(olist_closed_deals_dataset[[#This Row],[mql_id]], leads!A:A, leads!D:D, "Unknow" ) -> unknown | P45: =IF(olist_closed_deals_dataset[[#This Row],[declared_monthly_revenue]] >= 10000, "High Values ", IF(olist_closed_deals_dataset[[#This Row],[declared_monthly_revenue]] > 0, "Stander ", "No Revenue " )) -> No Revenue
A46: f72a53e19c3310188cedd074226312c9 | B46: 6e4a902d1054e4e17aa6eab87fac1c75 | C46: 34d40cdaf94010a1d05b0d6212f9e909 | D46: 2695de1affa7750089c0455f8ce27021 | E46: 43269.582 | F46: audio_video_electronics | G46: offline | H46: wolf | I46: Unknow | J46: Unknow | K46: Unknow | L46: reseller | M46: 0 | N46: 0 | O46: =_xlfn.XLOOKUP(olist_closed_deals_dataset[[#This Row],[mql_id]], leads!A:A, leads!D:D, "Unknow" ) -> direct_traffic | P46: =IF(olist_closed_deals_dataset[[#This Row],[declared_monthly_revenue]] >= 10000, "High Values ", IF(olist_closed_deals_dataset[[#This Row],[declared_monthly_revenue]] > 0, "Stander ", "No Revenue " )) -> No Revenue
A47: d25814a309be54d1d2279a4ff921ea28 | B47: 2d42ebcda99fd55f6f4bc2f1ca035d50 | C47: 4b339f9567d060bcea4f5136b9f5949e | D47: 9e4d1098a3b0f5da39b0bc48f9876645 | E47: 43201.125 | F47: home_decor | G47: online_big | H47: cat | I47: Unknow | J47: Unknow | K47: Unknow | L47: reseller | M47: 0 | N47: 0 | O47: =_xlfn.XLOOKUP(olist_closed_deals_dataset[[#This Row],[mql_id]], leads!A:A, leads!D:D, "Unknow" ) -> social | P47: =IF(olist_closed_deals_dataset[[#This Row],[declared_monthly_revenue]] >= 10000, "High Values ", IF(olist_closed_deals_dataset[[#This Row],[declared_monthly_revenue]] > 0, "Stander ", "No Revenue " )) -> No Revenue
A48: e3ed7cb7b47e4079cb9fef895846b3e2 | B48: 04843805947f0fc584fc1969b6e50fe7 | C48: 9d12ef1a7eca3ec58c545c678af7869c | D48: fbf4aef3f6915dc0c3c97d6812522f6a | E48: 43208.702 | F48: home_decor | G48: online_big | H48: cat | I48: Unknow | J48: Unknow | K48: Unknow | L48: manufacturer | M48: 0 | N48: 0 | O48: =_xlfn.XLOOKUP(olist_closed_deals_dataset[[#This Row],[mql_id]], leads!A:A, leads!D:D, "Unknow" ) -> social | P48: =IF(olist_closed_deals_dataset[[#This Row],[declared_monthly_revenue]] >= 10000, "High Values ", IF(olist_closed_deals_dataset[[#This Row],[declared_monthly_revenue]] > 0, "Stander ", "No Revenue " )) -> No Revenue
A49: 413e4eb37de01f40522e28ecdc268639 | B49: d9d057968270cdb30c14cba606d5dc90 | C49: 4b339f9567d060bcea4f5136b9f5949e | D49: 495d4e95a8cf8bbf8b432b612a2aa328 | E49: 43188.742 | F49: car_accessories | G49: online_medium | H49: Unknow | I49: Unknow | J49: Unknow | K49: Unknow | L49: reseller | M49: 0 | N49: 0 | O49: =_xlfn.XLOOKUP(olist_closed_deals_dataset[[#This Row],[mql_id]], leads!A:A, leads!D:D, "Unknow" ) -> unknown | P49: =IF(olist_closed_deals_dataset[[#This Row],[declared_monthly_revenue]] >= 10000, "High Values ", IF(olist_closed_deals_dataset[[#This Row],[declared_monthly_revenue]] > 0, "Stander ", "No Revenue " )) -> No Revenue
A50: c1e598764329cc9c377ef1d029be8ceb | B50: d4dcd3a31f5f19aea2f258a568517a4f | C50: fdb16d3cbbeb5798f2f66c4096be026d | D50: 060c0a26f19f4d66b42e0d8796688490 | E50: 43153.554 | F50: food_drink | G50: industry | H50: Unknow | I50: Unknow | J50: Unknow | K50: Unknow | L50: manufacturer | M50: 0 | N50: 0 | O50: =_xlfn.XLOOKUP(olist_closed_deals_dataset[[#This Row],[mql_id]], leads!A:A, leads!D:D, "Unknow" ) -> organic_search | P50: =IF(olist_closed_deals_dataset[[#This Row],[declared_monthly_revenue]] >= 10000, "High Values ", IF(olist_closed_deals_dataset[[#This Row],[declared_monthly_revenue]] > 0, "Stander ", "No Revenue " )) -> No Revenue
A51: 9cca8d684240e24dd459f2d439fae30c | B51: 28760737b4b82d4479ddff8db5e9f71f | C51: 9e4d1098a3b0f5da39b0bc48f9876645 | D51: 4ef15afb4b2723d8f3d81e51ec7afefe | E51: 43158.836 | F51: pet | G51: online_medium | H51: cat | I51: Unknow | J51: Unknow | K51: Unknow | L51: manufacturer | M51: 0 | N51: 0 | O51: =_xlfn.XLOOKUP(olist_closed_deals_dataset[[#This Row],[mql_id]], leads!A:A, leads!D:D, "Unknow" ) -> unknown | P51: =IF(olist_closed_deals_dataset[[#This Row],[declared_monthly_revenue]] >= 10000, "High Values ", IF(olist_closed_deals_dataset[[#This Row],[declared_monthly_revenue]] > 0, "Stander ", "No Revenue " )) -> No Revenue
A52: 0d99b130d767e50e22b528261ffe5550 | B52: 0dccb6973ef48a00fbcccfe907181ab0 | C52: 34d40cdaf94010a1d05b0d6212f9e909 | D52: a8387c01a09e99ce014107505b92388c | E52: 43262.503 | F52: food_supplement | G52: online_beginner | H52: cat | I52: Unknow | J52: Unknow | K52: Unknow | L52: reseller | M52: 0 | N52: 0 | O52: =_xlfn.XLOOKUP(olist_closed_deals_dataset[[#This Row],[mql_id]], leads!A:A, leads!D:D, "Unknow" ) -> organic_search | P52: =IF(olist_closed_deals_dataset[[#This Row],[declared_monthly_revenue]] >= 10000, "High Values ", IF(olist_closed_deals_dataset[[#This Row],[declared_monthly_revenue]] > 0, "Stander ", "No Revenue " )) -> No Revenue
A53: 7c9ac4388867d4cc3f1cf9c05ad7e944 | B53: 751e274377499a8503fd6243ad9c56f6 | C53: 9749123c950bf8363ace42cb1c2d0815 | D53: 4ef15afb4b2723d8f3d81e51ec7afefe | E53: 43311.608 | F53: audio_video_electronics | G53: online_big | H53: cat | I53: Unknow | J53: Unknow | K53: Unknow | L53: reseller | M53: 0 | N53: 0 | O53: =_xlfn.XLOOKUP(olist_closed_deals_dataset[[#This Row],[mql_id]], leads!A:A, leads!D:D, "Unknow" ) -> paid_search | P53: =IF(olist_closed_deals_dataset[[#This Row],[declared_monthly_revenue]] >= 10000, "High Values ", IF(olist_closed_deals_dataset[[#This Row],[declared_monthly_revenue]] > 0, "Stander ", "No Revenue " )) -> No Revenue
A54: 2c5d0b35798bffadf8f67ef0af84d183 | B54: 93a55b2252867fd7df54c78cbd5c6d95 | C54: 56bf83c4bb35763a51c2baab501b4c67 | D54: fbf4aef3f6915dc0c3c97d6812522f6a | E54: 43192.598 | F54: construction_tools_house_garden | G54: offline | H54: cat | I54: Unknow | J54: Unknow | K54: Unknow | L54: reseller | M54: 0 | N54: 0 | O54: =_xlfn.XLOOKUP(olist_closed_deals_dataset[[#This Row],[mql_id]], leads!A:A, leads!D:D, "Unknow" ) -> unknown | P54: =IF(olist_closed_deals_dataset[[#This Row],[declared_monthly_revenue]] >= 10000, "High Values ", IF(olist_closed_deals_dataset[[#This Row],[declared_monthly_revenue]] > 0, "Stander ", "No Revenue " )) -> No Revenue
A55: e5860ae00103b3869a25d940345bf0fd | B55: 1185ae3e5ac0463c854dad54fc8fc9e1 | C55: 34d40cdaf94010a1d05b0d6212f9e909 | D55: 495d4e95a8cf8bbf8b432b612a2aa328 | E55: 43203.535 | F55: bags_backpacks | G55: industry | H55: cat | I55: Unknow | J55: Unknow | K55: Unknow | L55: manufacturer | M55: 0 | N55: 0 | O55: =_xlfn.XLOOKUP(olist_closed_deals_dataset[[#This Row],[mql_id]], leads!A:A, leads!D:D, "Unknow" ) -> unknown | P55: =IF(olist_closed_deals_dataset[[#This Row],[declared_monthly_revenue]] >= 10000, "High Values ", IF(olist_closed_deals_dataset[[#This Row],[declared_monthly_revenue]] > 0, "Stander ", "No Revenue " )) -> No Revenue
... A71: 048bb2f901e2c6f99bc9d26b78b47129 | B71: fc813dd7e04b8a1c9c10e8e9c10cd5f9 | C71: 0a0fb2b07d841f84fb6714e35c723075 | D71: 4ef15afb4b2723d8f3d81e51ec7afefe | E71: 43276.815 | F71: music_instruments | G71: industry | H71: cat | I71: Unknow | J71: Unknow | K71: Unknow | L71: reseller | M71: 0 | N71: 0 | O71: =_xlfn.XLOOKUP(olist_closed_deals_dataset[[#This Row],[mql_id]], leads!A:A, leads!D:D, "Unknow" ) -> paid_search | P71: =IF(olist_closed_deals_dataset[[#This Row],[declared_monthly_revenue]] >= 10000, "High Values ", IF(olist_closed_deals_dataset[[#This Row],[declared_monthly_revenue]] > 0, "Stander ", "No Revenue " )) -> No Revenue
A72: 58caf27a48e7930aefd5437298d64a70 | B72: 922f6795c9e65f2485d4e63af76586ff | C72: 45749fb708130f78d0db07d8d80f030b | D72: 34d40cdaf94010a1d05b0d6212f9e909 | E72: 43364.763 | F72: bed_bath_table | G72: online_medium | H72: cat, wolf | I72: TRUE | J72: TRUE | K72: 5-20 | L72: reseller | M72: 50 | N72: 30000 | O72: =_xlfn.XLOOKUP(olist_closed_deals_dataset[[#This Row],[mql_id]], leads!A:A, leads!D:D, "Unknow" ) -> paid_search | P72: =IF(olist_closed_deals_dataset[[#This Row],[declared_monthly_revenue]] >= 10000, "High Values ", IF(olist_closed_deals_dataset[[#This Row],[declared_monthly_revenue]] > 0, "Stander ", "No Revenue " )) -> High Values
...

Sheet Marketing Summary
A1: origin | B1: Total Leads | C1: Total Deals | D1: Total Revenue | E1: Conversion Rate | F1: High Value Deals | G1: Stander Deals
A2: social | B2: =COUNTIF(leads!D:D, A2) -> 1350 | C2: =COUNTIF(deals!O:O, Table3[[#This Row],[origin]]) -> 75 | D2: =SUMIF(deals!O:O,Table3[[#This Row],[origin]],deals!N:N) -> 501000 | E2: =Table3[[#This Row],[Total Deals]] / Table3[[#This Row],[Total Leads]] -> 0.055555556 | F2: =COUNTIFS(deals!O:O,Table3[[#This Row],[origin]],deals!P:P, "High Values ") -> 3 | G2: =COUNTIFS(deals!O:O,Table3[[#This Row],[origin]],deals!P:P,"Stander ") -> 1
A3: paid_search | B3: =COUNTIF(leads!D:D, A3) -> 1586 | C3: =COUNTIF(deals!O:O, Table3[[#This Row],[origin]]) -> 195 | D3: =SUMIF(deals!O:O,Table3[[#This Row],[origin]],deals!N:N) -> 9169000 | E3: =Table3[[#This Row],[Total Deals]] / Table3[[#This Row],[Total Leads]] -> 0.12295082 | F3: =COUNTIFS(deals!O:O,Table3[[#This Row],[origin]],deals!P:P, "High Values ") -> 14 | G3: =COUNTIFS(deals!O:O,Table3[[#This Row],[origin]],deals!P:P,"Stander ") -> 1
A4: organic_search | B4: =COUNTIF(leads!D:D, A4) -> 2296 | C4: =COUNTIF(deals!O:O, Table3[[#This Row],[origin]]) -> 271 | D4: =SUMIF(deals!O:O,Table3[[#This Row],[origin]],deals!N:N) -> 51426000 | E4: =Table3[[#This Row],[Total Deals]] / Table3[[#This Row],[Total Leads]] -> 0.11803136 | F4: =COUNTIFS(deals!O:O,Table3[[#This Row],[origin]],deals!P:P, "High Values ") -> 13 | G4: =COUNTIFS(deals!O:O,Table3[[#This Row],[origin]],deals!P:P,"Stander ") -> 2
A5: direct_traffic | B5: =COUNTIF(leads!D:D, A5) -> 499 | C5: =COUNTIF(deals!O:O, Table3[[#This Row],[origin]]) -> 56 | D5: =SUMIF(deals!O:O,Table3[[#This Row],[origin]],deals!N:N) -> 60000 | E5: =Table3[[#This Row],[Total Deals]] / Table3[[#This Row],[Total Leads]] -> 0.11222445 | F5: =COUNTIFS(deals!O:O,Table3[[#This Row],[origin]],deals!P:P, "High Values ") -> 1 | G5: =COUNTIFS(deals!O:O,Table3[[#This Row],[origin]],deals!P:P,"Stander ") -> 0
A6: referral | B6: =COUNTIF(leads!D:D, A6) -> 284 | C6: =COUNTIF(deals!O:O, Table3[[#This Row],[origin]]) -> 24 | D6: =SUMIF(deals!O:O,Table3[[#This Row],[origin]],deals!N:N) -> 0 | E6: =Table3[[#This Row],[Total Deals]] / Table3[[#This Row],[Total Leads]] -> 0.084507042 | F6: =COUNTIFS(deals!O:O,Table3[[#This Row],[origin]],deals!P:P, "High Values ") -> 0 | G6: =COUNTIFS(deals!O:O,Table3[[#This Row],[origin]],deals!P:P,"Stander ") -> 0
A7: email | B7: =COUNTIF(leads!D:D, A7) -> 493 | C7: =COUNTIF(deals!O:O, Table3[[#This Row],[origin]]) -> 15 | D7: =SUMIF(deals!O:O,Table3[[#This Row],[origin]],deals!N:N) -> 15000 | E7: =Table3[[#This Row],[Total Deals]] / Table3[[#This Row],[Total Leads]] -> 0.030425963 | F7: =COUNTIFS(deals!O:O,Table3[[#This Row],[origin]],deals!P:P, "High Values ") -> 1 | G7: =COUNTIFS(deals!O:O,Table3[[#This Row],[origin]],deals!P:P,"Stander ") -> 0
A8: unknow | B8: =COUNTIF(leads!D:D, A8) -> 60 | C8: =COUNTIF(deals!O:O, Table3[[#This Row],[origin]]) -> 42 | D8: =SUMIF(deals!O:O,Table3[[#This Row],[origin]],deals!N:N) -> 150000 | E8: =Table3[[#This Row],[Total Deals]] / Table3[[#This Row],[Total Leads]] -> 0.7 | F8: =COUNTIFS(deals!O:O,Table3[[#This Row],[origin]],deals!P:P, "High Values ") -> 30 | G8: =COUNTIFS(deals!O:O,Table3[[#This Row],[origin]],deals!P:P,"Stander ") -> 0
A9: Total | B9: =SUBTOTAL(109,Table3[Total Leads]) -> 6568 | C9: =SUBTOTAL(109,Table3[Total Deals]) -> 678 | D9: =SUBTOTAL(109,Table3[Total Revenue]) -> 61321000 | E9: =C9/B9 -> 0.10322777 | F9: =SUBTOTAL(109,Table3[High Value Deals]) -> 62 | G9: =SUBTOTAL(109,Table3[Stander Deals]) -> 4
